<?xml version="1.0" ?>
<sdf version='1.11'>
  <model name='panda'>
    <link name='panda_link0'>
      <inertial>
        <pose>-0.041017999999999999 -0.00013999999999999999 0.049973999999999998 0 0 0</pose>
        <mass>0.62976900000000002</mass>
        <inertia>
          <ixx>0.00315</ixx>
          <ixy>8.2903999999999996e-07</ixy>
          <ixz>0.00014999999999999999</ixz>
          <iyy>0.0038800000000000002</iyy>
          <iyz>8.2299000000000006e-06</iyz>
          <izz>0.0042849999999999997</izz>
        </inertia>
      </inertial>
      <collision name='panda_link0_collision'>
        <pose>0 0 0 0 0 0</pose>
        <geometry>
          <mesh>
            <scale>1 1 1</scale>
            <uri>package://panda_description/meshes/collision/link0.stl</uri>
          </mesh>
        </geometry>
      </collision>
      <visual name='panda_link0_visual'>
        <pose>0 0 0 0 0 0</pose>
        <geometry>
          <mesh>
            <scale>1 1 1</scale>
            <uri>package://panda_description/meshes/visual/link0.dae</uri>
          </mesh>
        </geometry>
      </visual>
    </link>
    <joint name='panda_joint1' type='revolute'>
      <pose relative_to='panda_link0'>0 0 0.33300000000000002 0 0 0</pose>
      <parent>panda_link0</parent>
      <child>panda_link1</child>
      <axis>
        <xyz>0 0 1</xyz>
        <limit>
          <lower>-2.9670999999999998</lower>
          <upper>2.9670999999999998</upper>
          <effort>87</effort>
          <velocity>2.3925000000000001</velocity>
        </limit>
        <dynamics>
          <damping>0.0030000000000000001</damping>
          <friction>0</friction>
          <spring_reference>0</spring_reference>
          <spring_stiffness>0</spring_stiffness>
        </dynamics>
      </axis>
    </joint>
    <link name='panda_link1'>
      <pose relative_to='panda_joint1'>0 0 0 0 0 0</pose>
      <inertial>
        <pose>0.003875 0.002081 -0.047620000000000003 0 0 0</pose>
        <mass>4.9706840000000003</mass>
        <inertia>
          <ixx>0.70337000000000005</ixx>
          <ixy>-0.00013899999999999999</ixy>
          <ixz>0.0067720000000000002</ixz>
          <iyy>0.70660999999999996</iyy>
          <iyz>0.019168999999999999</iyz>
          <izz>0.0091170000000000001</izz>
        </inertia>
      </inertial>
      <collision name='panda_link1_collision'>
        <pose>0 0 0 0 0 0</pose>
        <geometry>
          <mesh>
            <scale>1 1 1</scale>
            <uri>package://panda_description/meshes/collision/link1.stl</uri>
          </mesh>
        </geometry>
      </collision>
      <visual name='panda_link1_visual'>
        <pose>0 0 0 0 0 0</pose>
        <geometry>
          <mesh>
            <scale>1 1 1</scale>
            <uri>package://panda_description/meshes/visual/link1.dae</uri>
          </mesh>
        </geometry>
      </visual>
    </link>
    <joint name='panda_joint2' type='revolute'>
      <pose relative_to='panda_link1'>0 0 0 -1.57079632679 0 0</pose>
      <parent>panda_link1</parent>
      <child>panda_link2</child>
      <axis>
        <xyz>0 0 1</xyz>
        <limit>
          <lower>-1.8326</lower>
          <upper>1.8326</upper>
          <effort>87</effort>
          <velocity>2.3925000000000001</velocity>
        </limit>
        <dynamics>
          <damping>0.0030000000000000001</damping>
          <friction>0</friction>
          <spring_reference>0</spring_reference>
          <spring_stiffness>0</spring_stiffness>
        </dynamics>
      </axis>
    </joint>
    <link name='panda_link2'>
      <pose relative_to='panda_joint2'>0 0 0 0 0 0</pose>
      <inertial>
        <pose>-0.0031410000000000001 -0.028719999999999999 0.0034949999999999998 0 0 0</pose>
        <mass>0.646926</mass>
        <inertia>
          <ixx>0.0079620000000000003</ixx>
          <ixy>-0.0039249999999999997</ixy>
          <ixz>0.010253999999999999</ixz>
          <iyy>0.02811</iyy>
          <iyz>0.00070399999999999998</iyz>
          <izz>0.025995000000000001</izz>
        </inertia>
      </inertial>
      <collision name='panda_link2_collision'>
        <pose>0 0 0 0 0 0</pose>
        <geometry>
          <mesh>
            <scale>1 1 1</scale>
            <uri>package://panda_description/meshes/collision/link2.stl</uri>
          </mesh>
        </geometry>
      </collision>
      <visual name='panda_link2_visual'>
        <pose>0 0 0 0 0 0</pose>
        <geometry>
          <mesh>
            <scale>1 1 1</scale>
            <uri>package://panda_description/meshes/visual/link2.dae</uri>
          </mesh>
        </geometry>
      </visual>
    </link>
    <joint name='panda_joint3' type='revolute'>
      <pose relative_to='panda_link2'>0 -0.316 0 1.57079632679 0 0</pose>
      <parent>panda_link2</parent>
      <child>panda_link3</child>
      <axis>
        <xyz>0 0 1</xyz>
        <limit>
          <lower>-2.9670999999999998</lower>
          <upper>2.9670999999999998</upper>
          <effort>87</effort>
          <velocity>2.3925000000000001</velocity>
        </limit>
        <dynamics>
          <damping>0.0030000000000000001</damping>
          <friction>0</friction>
          <spring_reference>0</spring_reference>
          <spring_stiffness>0</spring_stiffness>
        </dynamics>
      </axis>
    </joint>
    <link name='panda_link3'>
      <pose relative_to='panda_joint3'>0 0 0 0 0 0</pose>
      <inertial>
        <pose>0.027518000000000001 0.039252000000000002 -0.066502000000000006 0 0 0</pose>
        <mass>3.2286039999999998</mass>
        <inertia>
          <ixx>0.037241999999999997</ixx>
          <ixy>-0.0047609999999999996</ixy>
          <ixz>-0.011396</ixz>
          <iyy>0.036155</iyy>
          <iyz>-0.012805</iyz>
          <izz>0.010829999999999999</izz>
        </inertia>
      </inertial>
      <collision name='panda_link3_collision'>
        <pose>0 0 0 0 0 0</pose>
        <geometry>
          <mesh>
            <scale>1 1 1</scale>
            <uri>package://panda_description/meshes/collision/link3.stl</uri>
          </mesh>
        </geometry>
      </collision>
      <visual name='panda_link3_visual'>
        <pose>0 0 0 0 0 0</pose>
        <geometry>
          <mesh>
            <scale>1 1 1</scale>
            <uri>package://panda_description/meshes/visual/link3.dae</uri>
          </mesh>
        </geometry>
      </visual>
    </link>
    <joint name='panda_joint4' type='revolute'>
      <pose relative_to='panda_link3'>0.082500000000000004 0 0 1.57079632679 0 0</pose>
      <parent>panda_link3</parent>
      <child>panda_link4</child>
      <axis>
        <xyz>0 0 1</xyz>
        <limit>
          <lower>-3.1415999999999999</lower>
          <upper>0.087300000000000003</upper>
          <effort>87</effort>
          <velocity>2.3925000000000001</velocity>
        </limit>
        <dynamics>
          <damping>0.0030000000000000001</damping>
          <friction>0</friction>
          <spring_reference>0</spring_reference>
          <spring_stiffness>0</spring_stiffness>
        </dynamics>
      </axis>
    </joint>
    <link name='panda_link4'>
      <pose relative_to='panda_joint4'>0 0 0 0 0 0</pose>
      <inertial>
        <pose>-0.053170000000000002 0.104419 0.027453999999999999 0 0 0</pose>
        <mass>3.5878950000000001</mass>
        <inertia>
          <ixx>0.025853000000000001</ixx>
          <ixy>0.007796</ixy>
          <ixz>-0.0013320000000000001</ixz>
          <iyy>0.019552</iyy>
          <iyz>0.0086409999999999994</iyz>
          <izz>0.028323000000000001</izz>
        </inertia>
      </inertial>
      <collision name='panda_link4_collision'>
        <pose>0 0 0 0 0 0</pose>
        <geometry>
          <mesh>
            <scale>1 1 1</scale>
            <uri>package://panda_description/meshes/collision/link4.stl</uri>
          </mesh>
        </geometry>
      </collision>
      <visual name='panda_link4_visual'>
        <pose>0 0 0 0 0 0</pose>
        <geometry>
          <mesh>
            <scale>1 1 1</scale>
            <uri>package://panda_description/meshes/visual/link4.dae</uri>
          </mesh>
        </geometry>
      </visual>
    </link>
    <joint name='panda_joint5' type='revolute'>
      <pose relative_to='panda_link4'>-0.082500000000000004 0.38400000000000001 0 -1.57079632679 0 0</pose>
      <parent>panda_link4</parent>
      <child>panda_link5</child>
      <axis>
        <xyz>0 0 1</xyz>
        <limit>
          <lower>-2.9670999999999998</lower>
          <upper>2.9670999999999998</upper>
          <effort>12</effort>
          <velocity>2.871</velocity>
        </limit>
        <dynamics>
          <damping>0.0030000000000000001</damping>
          <friction>0</friction>
          <spring_reference>0</spring_reference>
          <spring_stiffness>0</spring_stiffness>
        </dynamics>
      </axis>
    </joint>
    <link name='panda_link5'>
      <pose relative_to='panda_joint5'>0 0 0 0 0 0</pose>
      <inertial>
        <pose>-0.011953 0.041064999999999997 -0.038436999999999999 0 0 0</pose>
        <mass>1.225946</mass>
        <inertia>
          <ixx>0.035548999999999997</ixx>
          <ixy>-0.002117</ixy>
          <ixz>-0.0040369999999999998</ixz>
          <iyy>0.029474</iyy>
          <iyz>0.00022900000000000001</iyz>
          <izz>0.0086269999999999993</izz>
        </inertia>
      </inertial>
      <collision name='panda_link5_collision'>
        <pose>0 0 0 0 0 0</pose>
        <geometry>
          <mesh>
            <scale>1 1 1</scale>
            <uri>package://panda_description/meshes/collision/link5.stl</uri>
          </mesh>
        </geometry>
      </collision>
      <visual name='panda_link5_visual'>
        <pose>0 0 0 0 0 0</pose>
        <geometry>
          <mesh>
            <scale>1 1 1</scale>
            <uri>package://panda_description/meshes/visual/link5.dae</uri>
          </mesh>
        </geometry>
      </visual>
    </link>
    <joint name='panda_joint6' type='revolute'>
      <pose relative_to='panda_link5'>0 0 0 1.57079632679 0 0</pose>
      <parent>panda_link5</parent>
      <child>panda_link6</child>
      <axis>
        <xyz>0 0 1</xyz>
        <limit>
          <lower>-0.087300000000000003</lower>
          <upper>3.8222999999999998</upper>
          <effort>12</effort>
          <velocity>2.871</velocity>
        </limit>
        <dynamics>
          <damping>0.0030000000000000001</damping>
          <friction>0</friction>
          <spring_reference>0</spring_reference>
          <spring_stiffness>0</spring_stiffness>
        </dynamics>
      </axis>
    </joint>
    <link name='panda_link6'>
      <pose relative_to='panda_joint6'>0 0 0 0 0 0</pose>
      <inertial>
        <pose>0.060149000000000001 -0.014116999999999999 -0.010517 0 0 0</pose>
        <mass>1.666555</mass>
        <inertia>
          <ixx>0.001964</ixx>
          <ixy>0.00010900000000000001</ixy>
          <ixz>-0.001158</ixz>
          <iyy>0.0043540000000000002</iyy>
          <iyz>0.00034099999999999999</iyz>
          <izz>0.0054330000000000003</izz>
        </inertia>
      </inertial>
      <collision name='panda_link6_collision'>
        <pose>0 0 0 0 0 0</pose>
        <geometry>
          <mesh>
            <scale>1 1 1</scale>
            <uri>package://panda_description/meshes/collision/link6.stl</uri>
          </mesh>
        </geometry>
      </collision>
      <visual name='panda_link6_visual'>
        <pose>0 0 0 0 0 0</pose>
        <geometry>
          <mesh>
            <scale>1 1 1</scale>
            <uri>package://panda_description/meshes/visual/link6.dae</uri>
          </mesh>
        </geometry>
      </visual>
    </link>
    <joint name='panda_joint7' type='revolute'>
      <pose relative_to='panda_link6'>0.087999999999999995 0 0 1.57079632679 0 0</pose>
      <parent>panda_link6</parent>
      <child>panda_link7</child>
      <axis>
        <xyz>0 0 1</xyz>
        <limit>
          <lower>-2.9670999999999998</lower>
          <upper>2.9670999999999998</upper>
          <effort>12</effort>
          <velocity>2.871</velocity>
        </limit>
        <dynamics>
          <damping>0.0030000000000000001</damping>
          <friction>0</friction>
          <spring_reference>0</spring_reference>
          <spring_stiffness>0</spring_stiffness>
        </dynamics>
      </axis>
    </joint>
    <link name='panda_link7'>
      <pose relative_to='panda_joint7'>0 0 0 0 0 0</pose>
      <inertial>
        <pose>0.0017561014923937609 0.001388201581866041 0.099156442983455717 0 0 0</pose>
        <mass>1.465522</mass>
        <inertia>
          <ixx>0.016396041602866059</ixx>
          <ixy>0.00039496396473183529</ixy>
          <ixz>-0.00070411561565401231</ixz>
          <iyy>0.013973402524881631</iyy>
          <iyz>-0.001053808768508498</iyz>
          <izz>0.0066753082423586883</izz>
        </inertia>
      </inertial>
      <collision name='panda_link7_collision'>
        <pose>0 0 0 0 0 0</pose>
        <geometry>
          <mesh>
            <scale>1 1 1</scale>
            <uri>package://panda_description/meshes/collision/link7.stl</uri>
          </mesh>
        </geometry>
      </collision>
      <collision name='panda_link7_fixed_joint_lump__panda_hand_collision_1'>
        <pose>0 0 0.107 0 0 -0.78539816339699997</pose>
        <geometry>
          <mesh>
            <scale>1 1 1</scale>
            <uri>package://panda_description/meshes/collision/hand.stl</uri>
          </mesh>
        </geometry>
      </collision>
      <visual name='panda_link7_visual'>
        <pose>0 0 0 0 0 0</pose>
        <geometry>
          <mesh>
            <scale>1 1 1</scale>
            <uri>package://panda_description/meshes/visual/link7.dae</uri>
          </mesh>
        </geometry>
      </visual>
      <visual name='panda_link7_fixed_joint_lump__panda_hand_visual_1'>
        <pose>0 0 0.107 0 0 -0.78539816339699997</pose>
        <geometry>
          <mesh>
            <scale>1 1 1</scale>
            <uri>package://panda_description/meshes/visual/hand.dae</uri>
          </mesh>
        </geometry>
      </visual>
    </link>
    <joint name='panda_finger_joint1' type='prismatic'>
      <pose relative_to='panda_link7'>0 0 0.16539999999999999 0 0 -0.78539816339699997</pose>
      <parent>panda_link7</parent>
      <child>panda_leftfinger</child>
      <axis>
        <xyz>0 1 0</xyz>
        <limit>
          <lower>0</lower>
          <upper>0.040000000000000001</upper>
          <effort>20</effort>
          <velocity>0.20000000000000001</velocity>
        </limit>
        <dynamics>
          <damping>0.29999999999999999</damping>
          <friction>0</friction>
          <spring_reference>0</spring_reference>
          <spring_stiffness>0</spring_stiffness>
        </dynamics>
      </axis>
    </joint>
    <link name='panda_leftfinger'>
      <pose relative_to='panda_finger_joint1'>0 0 0 0 0 0</pose>
      <inertial>
        <pose>0 0 0 0 0 0</pose>
        <mass>0.014999999999999999</mass>
        <inertia>
          <ixx>2.3750000000000001e-06</ixx>
          <ixy>0</ixy>
          <ixz>0</ixz>
          <iyy>2.3750000000000001e-06</iyy>
          <iyz>0</iyz>
          <izz>7.5000000000000002e-07</izz>
        </inertia>
      </inertial>
      <collision name='panda_leftfinger_collision'>
        <pose>0 0 0 0 0 0</pose>
        <geometry>
          <mesh>
            <scale>1 1 1</scale>
            <uri>package://panda_description/meshes/collision/finger.stl</uri>
          </mesh>
        </geometry>
      </collision>
      <visual name='panda_leftfinger_visual'>
        <pose>0 0 0 0 0 0</pose>
        <geometry>
          <mesh>
            <scale>1 1 1</scale>
            <uri>package://panda_description/meshes/visual/finger.dae</uri>
          </mesh>
        </geometry>
      </visual>
    </link>
    <joint name='panda_finger_joint2' type='prismatic'>
      <pose relative_to='panda_link7'>0 0 0.16539999999999999 0 0 -0.78539816339699997</pose>
      <parent>panda_link7</parent>
      <child>panda_rightfinger</child>
      <axis>
        <xyz>0 -1 0</xyz>
        <mimic joint='panda_finger_joint1'>
          <multiplier>1</multiplier>
          <offset>0</offset>
          <reference>0</reference>
        </mimic>
        <limit>
          <lower>0</lower>
          <upper>0.040000000000000001</upper>
          <effort>20</effort>
          <velocity>0.20000000000000001</velocity>
        </limit>
        <dynamics>
          <damping>0.29999999999999999</damping>
          <friction>0</friction>
          <spring_reference>0</spring_reference>
          <spring_stiffness>0</spring_stiffness>
        </dynamics>
      </axis>
    </joint>
    <link name='panda_rightfinger'>
      <pose relative_to='panda_finger_joint2'>0 0 0 0 0 0</pose>
      <inertial>
        <pose>0 0 0 0 0 0</pose>
        <mass>0.14999999999999999</mass>
        <inertia>
          <ixx>2.3750000000000001e-06</ixx>
          <ixy>0</ixy>
          <ixz>0</ixz>
          <iyy>2.3750000000000001e-06</iyy>
          <iyz>0</iyz>
          <izz>7.5000000000000002e-07</izz>
        </inertia>
      </inertial>
      <collision name='panda_rightfinger_collision'>
        <pose>0 0 0 0 0 -3.1415926535895871</pose>
        <geometry>
          <mesh>
            <scale>1 1 1</scale>
            <uri>package://panda_description/meshes/collision/finger.stl</uri>
          </mesh>
        </geometry>
      </collision>
      <visual name='panda_rightfinger_visual'>
        <pose>0 0 0 0 0 -3.1415926535895871</pose>
        <geometry>
          <mesh>
            <scale>1 1 1</scale>
            <uri>package://panda_description/meshes/visual/finger.dae</uri>
          </mesh>
        </geometry>
      </visual>
    </link>

    <joint name="panda_camera_joint" type="fixed">
      <pose relative_to="panda_link7">0.01 0 0.01 0 0 0</pose>
      <parent>panda_link7</parent>
      <child>rgbd_camera_link</child>
    </joint>
    <link name="rgbd_camera_link">
      <pose relative_to="panda_camera_joint">0 0 0 0 0 0</pose>
    </link>

    <joint name="panda_joint8" type="fixed">
      <pose relative_to="panda_link7">0 0 0.107 0 0 0</pose>
      <parent>panda_link7</parent>
      <child>panda_link8</child>
    </joint>
    <link name='panda_link8'>
      <pose relative_to="panda_joint8">0 0 0 0 0 0</pose>
    </link>

    <joint name="panda_joint9" type="fixed">
      <pose relative_to="panda_link8">0 0 0 0 0 -0.78539816339699997</pose>
      <parent>panda_link8</parent>
      <child>panda_hand</child>
    </joint>
    <link name='panda_hand'>
      <pose relative_to="panda_joint9">0 0 0 0 0 0</pose>
    </link>

    <joint name="panda_joint10" type="fixed">
      <pose relative_to="panda_hand">0 0 0.100 0 0 0</pose>
      <parent>panda_hand</parent>
      <child>panda_tcp</child>
    </joint>
    <link name='panda_tcp'>
      <pose relative_to="panda_joint10">0 0 0 0 0 0</pose>
    </link>

    <ros2_control name="MyRobotHardware" type="system">
        <hardware>
            <plugin>gz_ros2_control/GazeboSimSystem</plugin>
        </hardware>

        <!-- List all joints with control interfaces -->
        <joint name="panda_joint1">
            <command_interface name="position"/>
            <state_interface name="position">
              <param name="initial_value">0</param>
            </state_interface>
            <state_interface name="velocity"/>
        </joint>
        <joint name="panda_joint2">
            <command_interface name="position"/>
            <state_interface name="position">
              <param name="initial_value">0</param>
            </state_interface>
            <state_interface name="velocity"/>
        </joint>
        <joint name="panda_joint3">
            <command_interface name="position"/>
            <state_interface name="position">
              <param name="initial_value">0</param>
            </state_interface>
            <state_interface name="velocity"/>
        </joint>
        <joint name="panda_joint4">
            <command_interface name="position"/>
            <state_interface name="position">
              <param name="initial_value">0</param>
            </state_interface>
            <state_interface name="velocity"/>
        </joint>
        <joint name="panda_joint5">
            <command_interface name="position"/>
            <state_interface name="position">
              <param name="initial_value">0</param>
            </state_interface>
            <state_interface name="velocity"/>
        </joint>
        <joint name="panda_joint6">
            <command_interface name="position"/>
            <state_interface name="position">
              <param name="initial_value">1.57</param>
            </state_interface>
            <state_interface name="velocity"/>
        </joint>
        <joint name="panda_joint7">
            <command_interface name="position"/>
            <state_interface name="position">
              <param name="initial_value">0</param>
            </state_interface>
            <state_interface name="velocity"/>
        </joint>
        <joint name="panda_finger_joint1">
            <command_interface name="position"/>
            <state_interface name="position">
              <param name="initial_value">0.01</param>
            </state_interface>
            <state_interface name="velocity"/>
        </joint>

    </ros2_control>

    <plugin name='gz_ros2_control::GazeboSimROS2ControlPlugin' filename='libgz_ros2_control-system.so'>
      <parameters>/home/brian/arm_driver_ws/install/panda_moveit_config/share/panda_moveit_config/config/controllers.yaml</parameters>
    </plugin>

  </model>
</sdf>
